Workbook

Sheet Инструкция
A1: Обзвон стоматологий Костаная
A2: Заполнять только жёлтые клетки на листе «Обзвон». Остальное считается само.
B4: СЕМЬ ЗВОНКОВ НА КЛИНИКУ, РАСТЯНУТЫХ НА НЕДЕЛЮ
B5: Каждая колонка в таблице — это один звонок. «1» и «2» означают два звонка в один и тот же день с интервалом десять минут.
A6: Раб. | B6: Вторник или среда, около 11:00 — один звонок.
A7: Веч.1 / Веч.2 | B7: Будний вечер: первый в 20:30, второй в 20:40.
A8: Сб.1 / Сб.2 | B8: Суббота: первый в 13:00, второй в 13:10.
A9: Вс.1 / Вс.2 | B9: Воскресенье: первый в 12:00, второй в 12:10.
B10: Повтор через десять минут обязателен: один неотвеченный звонок ничего не доказывает, телефон могли просто не услышать.
B11: СКОЛЬКО ЖДАТЬ В ОДНОМ ЗВОНКЕ: шесть гудков, потом класть трубку. Это про длительность звонка, а не про их количество.
B13: ЧТО ЗНАЧИТ ПРИОРИТЕТ
B14: Это размер окна, когда телефон молчит, а не оценка клиники.
A15: A | B15: Закрываются в 19:00–22:00 или есть обед. Окно широкое, до 14 часов в сутки. Звонить первыми.
A16: B | B16: Часы в 2ГИС не указаны — окно НЕИЗВЕСТНО. Это не «средние», это «пока не знаем». Выяснится на дневном звонке, и группа разойдётся по A и C.
A17: C | B17: Работают до 23:00–24:00 или круглосуточно. Вечернего окна почти нет. В последнюю очередь и только если останется время.
B20: КОДЫ
A21: Ч | B21: ответил живой человек
A22: А | B22: автоответчик или голосовое сообщение
A23: Г | B23: гудки, никто не взял трубку
A24: З | B24: занято
A25: Н | B25: номер недоступен или не существует
A26: С | B26: сбросили звонок
B27: Клетка подсвечивается сама: зелёным если ответили, красным если гудки.
B29: ПРИМЕР ЗАПОЛНЕНИЯ
A30: Клиника | B30: Раб. | C30: Веч.1 | D30: Веч.2 | E30: Сб.1 | F30: Сб.2 | G30: Вс.1 | H30: Вс.2 | I30: Заметки
A31: Ажар Дент | B31: Ч | C31: Г | D31: Г | E31: Г | F31: А | G31: Г | H31: Г | I31: Днём ответил администратор. Сказала, что вечером никого нет. Автоответчик в субботу: «клиника работает с 9 до 19». Перезвонили в пн 09:14.
B34: ЕСЛИ СНЯЛИ ТРУБКУ — СКРИПТ
B35: Главное в этом звонке — узнать про неявки. Всё остальное второстепенно.
A36: Начало | B36: «Здравствуйте! Меня зовут ___. Я не пациент — я делаю сервис для стоматологий и сейчас изучаю, как у клиник устроена запись. Три вопроса, если найдётся минута.»
A37: 1. | B37: «Скажите, у вас бывает так, что пациент записался, а потом не пришёл?»
A38: 2. | B38: «А примерно сколько таких было на прошлой неделе?» — нужно число, а не «часто» или «бывает». Записать в колонку «Неявки: сколько».
A39: 3. | B39: «И что вы с этим сейчас делаете?» — САМЫЙ ВАЖНЫЙ ВОПРОС. Дать договорить, не подсказывать варианты. Записать в «Что делают сейчас».
A40: если напоминают | B40: «А кто напоминает и за сколько до приёма? Помогает, стало меньше?»
A41: Закрытие | B41: «И последнее: если человек звонит вечером после закрытия — он может к вам записаться?» Потом: «Спасибо большое, вы очень помогли.»
B43: ЧЕГО НЕ ДЕЛАТЬ В ЭТОМ РАЗГОВОРЕ
B44: Не рассказывать, что мы делаем сервис против неявок. Как только человек услышит про решение, он начнёт вежливо соглашаться, и ответ обесценится. Сначала узнаём, рассказываем потом и не в этом звонке.
B45: Не спрашивать «а вам было бы интересно...». Мнения о будущем ничего не стоят, нужны факты про прошлую неделю.
B46: Не советовать и не спорить, даже если решение кажется очевидным.
B48: ЧЕГО ДЕЛАТЬ НЕЛЬЗЯ ВООБЩЕ
B49: Не притворяться пациентом. Ни при каких условиях.
...

Sheet Обзвон
A1: № | B1: Клиника | C1: Телефон | D1: Доп. телефон | E1: Адрес | F1: Часы работы | G1: Приор. | H1: Раб. | I1: Веч.1 | J1: Веч.2 | K1: Сб.1 | L1: Сб.2 | M1: Вс.1 | N1: Вс.2 | O1: Гудков | P1: Ответов | Q1: Перезвонили | R1: Неявки: сколько | S1: Что делают сейчас | T1: Заметки
A2: 1 | B2: Стоматологический центр "PROTETIKA" | C2: +7 776 237 84 05 | D2: +7 (7142) 91 78 89 | E2: пр. Абая, д. 112 | F2: не указаны | G2: B | O2: =COUNTIF(I2:N2,"Г") | P2: =COUNTIF(I2:N2,"Ч")
A3: 2 | B3: Стоматологический кабинет "МОЙ ДОКТОР" | C3: +7 705 450 98 95 | E3: ул. Аль-Фараби, д. 117 | F3: 09:00-18:00 | G3: A | O3: =COUNTIF(I3:N3,"Г") | P3: =COUNTIF(I3:N3,"Ч")
A4: 3 | B4: Стоматология "STOMAX 72+" | C4: +7 (7142) 56 60 82 | D4: +7 777 792 09 81 | E4: ул. Бородина, д. 234Б | F4: не указаны | G4: B | O4: =COUNTIF(I4:N4,"Г") | P4: =COUNTIF(I4:N4,"Ч")
A5: 4 | B5: DENTAL в 7 мкр | C5: +7 (7142) 22 36 77 | D5: +7 701 068 33 37 | E5: мкр 7, д. 17 | F5: не указаны | G5: B | O5: =COUNTIF(I5:N5,"Г") | P5: =COUNTIF(I5:N5,"Ч")
A6: 5 | B6: DENTAL на Береке | C6: +7 (7142) 28 42 96 | D6: +7 701 059 33 36 | E6: мкр Береке, д. 50 | F6: не указаны | G6: B | O6: =COUNTIF(I6:N6,"Г") | P6: =COUNTIF(I6:N6,"Ч")
A7: 6 | B7: DENTAL на Чехова | C7: +7 (7142) 56 76 73 | D7: +7 701 673 33 80 | E7: ул. Чехова, д. 125 | F7: 09:00-19:00 | G7: A | O7: =COUNTIF(I7:N7,"Г") | P7: =COUNTIF(I7:N7,"Ч")
A8: 7 | B8: DENTAL на Чкалова | C8: +7 (7142) 26 42 16 | D8: +7 701 950 33 38 | E8: ул. Чкалова, д. 7 | F8: 09:00-19:00 | G8: A | O8: =COUNTIF(I8:N8,"Г") | P8: =COUNTIF(I8:N8,"Ч")
A9: 8 | B9: DENTAL на Каирбекова | C9: +7 (7142) 56 48 66 | D9: +7 701 064 33 31 | E9: ул. Каирбекова, д. 389 | F9: не указаны | G9: B | O9: =COUNTIF(I9:N9,"Г") | P9: =COUNTIF(I9:N9,"Ч")
A10: 9 | B10: ЖЕМЧУЖИНА СТОМЕД на Пушкина | C10: +7 (7142) 50 33 00 | D10: +7 707 550 63 55 | E10: ул. Пушкина, д. 54 | F10: 09:00-20:00 | G10: A | O10: =COUNTIF(I10:N10,"Г") | P10: =COUNTIF(I10:N10,"Ч")
A11: 10 | B11: ЖЕМЧУЖИНА СТОМЕД на Уральской | C11: +7 (7142) 28 01 69 | D11: +7 (7142) 50 33 00 | E11: ул. Уральская, д. 14 | F11: не указаны | G11: B | O11: =COUNTIF(I11:N11,"Г") | P11: =COUNTIF(I11:N11,"Ч")
A12: 11 | B12: ОДОНТИК | C12: +7 777 236 38 15 | E12: ул. Урожайная, д. 16 | F12: 09:00-18:00 | G12: A | O12: =COUNTIF(I12:N12,"Г") | P12: =COUNTIF(I12:N12,"Ч")
A13: 12 | B13: КОКТЕМ-3 | C13: +7 (7142) 54 96 05 | D13: +7 747 752 82 53 | E13: ул. Тауелсиздик, д. 87 | F13: не указаны | G13: B | O13: =COUNTIF(I13:N13,"Г") | P13: =COUNTIF(I13:N13,"Ч")
A14: 13 | B14: ТУЛЕШ | C14: +7 (7142) 22 65 55 | D14: +7 776 999 32 29 | E14: мкр 7, д. 15 | F14: не указаны | G14: B | O14: =COUNTIF(I14:N14,"Г") | P14: =COUNTIF(I14:N14,"Ч")
A15: 14 | B15: MIA DENTA | C15: +7 (7142) 39 66 43 | D15: +7 777 972 44 55 | E15: ул. Алтынсарина, д. 32 | F15: не указаны | G15: B | O15: =COUNTIF(I15:N15,"Г") | P15: =COUNTIF(I15:N15,"Ч")
A16: 15 | B16: Медцентр МЕДИКУС | C16: +7 (7142) 28 25 43 | D16: +7 777 298 53 42 | E16: ул. Строительная, д. 6 | F16: не указаны | G16: B | O16: =COUNTIF(I16:N16,"Г") | P16: =COUNTIF(I16:N16,"Ч")
A17: 16 | B17: ДЕНТАЛ-СЕРВИС | C17: +7 707 370 17 99 | E17: ул. Абая, д. 63 | F17: 09:00-18:00 | G17: A | O17: =COUNTIF(I17:N17,"Г") | P17: =COUNTIF(I17:N17,"Ч")
A18: 17 | B18: ЭРА | C18: +7 (7142) 56 46 46 | D18: +7 747 601 93 60 | E18: ул. Каирбекова, д. 377 | F18: не указаны | G18: B | O18: =COUNTIF(I18:N18,"Г") | P18: =COUNTIF(I18:N18,"Ч")
A19: 18 | B19: ТОТЫ | C19: +7 (7142) 91 73 29 | D19: +7 701 473 36 63 | E19: ул. Алтынсарина, д. 153 | F19: не указаны | G19: B | O19: =COUNTIF(I19:N19,"Г") | P19: =COUNTIF(I19:N19,"Ч")
A20: 19 | B20: НАРИ-С | C20: +7 (7142) 26 16 78 | D20: +7 747 430 62 39 | E20: пр. Абая, д. 12 | F20: 10:00-17:00 | G20: A | O20: =COUNTIF(I20:N20,"Г") | P20: =COUNTIF(I20:N20,"Ч")
A21: 20 | B21: ЗУБ и К | C21: +7 (7142) 26 72 29 | D21: +7 776 079 19 25 | E21: ул. Чкалова, д. 14 | F21: 09:00-17:00 | G21: A | O21: =COUNTIF(I21:N21,"Г") | P21: =COUNTIF(I21:N21,"Ч")
A22: 21 | B22: Стоматология 32 | C22: +7 (7142) 55 30 03 | D22: +7 776 127 64 82 | E22: ул. Кобланды батыра, д. 38 | F22: не указаны | G22: B | O22: =COUNTIF(I22:N22,"Г") | P22: =COUNTIF(I22:N22,"Ч")
A23: 22 | B23: Стоматология на Майлина | C23: +7 (7142) 57 25 65 | D23: +7 777 255 32 63 | E23: ул. Майлина, д. 18 | F23: не указаны | G23: B | O23: =COUNTIF(I23:N23,"Г") | P23: =COUNTIF(I23:N23,"Ч")
A24: 23 | B24: Стоматология в мкр 9 | C24: +7 777 328 57 66 | D24: +7 777 562 16 33 | E24: мкр 9, д. 4А | F24: не указаны | G24: B | O24: =COUNTIF(I24:N24,"Г") | P24: =COUNTIF(I24:N24,"Ч")
A25: 24 | B25: Стоматология на Аль-Фараби 123 | C25: +7 (7142) 90 02 39 | D25: +7 777 134 16 88 | E25: пр. Аль-Фараби, д. 123 | F25: 09:00-18:00 | G25: A | O25: =COUNTIF(I25:N25,"Г") | P25: =COUNTIF(I25:N25,"Ч")
A26: 25 | B26: ВИТА | C26: +7 (7142) 51 20 08 | D26: +7 777 302 70 23 | E26: ул. Абая, д. 160 | F26: не указаны | G26: B | O26: =COUNTIF(I26:N26,"Г") | P26: =COUNTIF(I26:N26,"Ч")
A27: 26 | B27: НУР | C27: +7 (7142) 28 34 29 | D27: +7 747 131 98 77 | E27: ул. Мауленова, д. 12/4 | F27: 10:00-18:00 | G27: A | O27: =COUNTIF(I27:N27,"Г") | P27: =COUNTIF(I27:N27,"Ч")
A28: 27 | B28: АЙМАН | C28: +7 (7142) 28 46 72 | D28: +7 705 138 04 70 | E28: ул. Карбышева, д. 19 | F28: не указаны | G28: B | O28: =COUNTIF(I28:N28,"Г") | P28: =COUNTIF(I28:N28,"Ч")
A29: 28 | B29: ЕМ БЕРГЕН | C29: +7 (7142) 55 38 13 | D29: +7 777 139 51 27 | E29: ул. Кобланды батыра, д. 31/1 | F29: не указаны | G29: B | O29: =COUNTIF(I29:N29,"Г") | P29: =COUNTIF(I29:N29,"Ч")
... A31: 30 | B31: ДАНТИСТ | C31: +7 (7142) 57 47 01 | D31: +7 705 746 99 02 | E31: ул. Бертрана Рубинштейна, д. 81 | F31: не указаны | G31: B | O31: =COUNTIF(I31:N31,"Г") | P31: =COUNTIF(I31:N31,"Ч")
A32: 31 | B32: BEST | C32: +7 705 832 30 57 | E32: ул. Байтурсынова, д. 45 | F32: не указаны | G32: B | O32: =COUNTIF(I32:N32,"Г") | P32: =COUNTIF(I32:N32,"Ч")
A33: 32 | B33: ЖЕМЧУЖИНА СТОМЕД в мкр 8 | C33: +7 (7142) 22 58 03 | D33: +7 707 662 60 27 | E33: мкр 8, д. 19 | F33: не указаны | G33: B | O33: =COUNTIF(I33:N33,"Г") | P33: =COUNTIF(I33:N33,"Ч")
A34: 33 | B34: PREMIUM DENT | C34: +7 (7142) 50 33 27 | D34: +7 777 391 25 95 | E34: ул. Гоголя, д. 87 | F34: 09:00-17:00 | G34: A | O34: =COUNTIF(I34:N34,"Г") | P34: =COUNTIF(I34:N34,"Ч")
A35: 34 | B35: Кабинет на Кобланды батыра 21Б | C35: +7 (7142) 75 35 66 | D35: +7 705 506 37 53 | E35: ул. Кобланды батыра, д. 21Б | F35: не указаны | G35: B | O35: =COUNTIF(I35:N35,"Г") | P35: =COUNTIF(I35:N35,"Ч")
A36: 35 | B36: БЕРИК & К | C36: +7 701 456 95 57 | D36: +7 (7132) 54 30 31 | E36: ул. Касымханова, д. 114 | F36: 09:00-18:00 | G36: A | O36: =COUNTIF(I36:N36,"Г") | P36: =COUNTIF(I36:N36,"Ч")
A37: 36 | B37: Кабинет при аптеке «Домик аптекаря» | C37: +7 777 379 13 74 | D37: +7 777 379 13 75 | E37: мкр 8, д. 8А | F37: не указаны | G37: B | O37: =COUNTIF(I37:N37,"Г") | P37: =COUNTIF(I37:N37,"Ч")
A38: 37 | B38: Стоматология на Леонида Беды | C38: +7 777 304 15 63 | D38: +7 701 764 06 80 | E38: ул. Леонида Беды, д. 26 | F38: не указаны | G38: B | O38: =COUNTIF(I38:N38,"Г") | P38: =COUNTIF(I38:N38,"Ч")
A39: 38 | B39: ДЕНТА | C39: +7 (7142) 53 21 34 | E39: ул. Пушкина, д. 65 | F39: не указаны | G39: B | O39: =COUNTIF(I39:N39,"Г") | P39: =COUNTIF(I39:N39,"Ч")
A40: 39 | B40: А-СТОМ | C40: +7 (7142) 54 34 86 | D40: +7 777 230 53 80 | E40: ул. Амангельды, д. 76 | F40: не указаны | G40: B | O40: =COUNTIF(I40:N40,"Г") | P40: =COUNTIF(I40:N40,"Ч")
A41: 40 | B41: Медцентр САЕ | C41: +7 (7142) 56 52 52 | E41: ул. Каирбекова, д. 369 | F41: не указаны | G41: B | O41: =COUNTIF(I41:N41,"Г") | P41: =COUNTIF(I41:N41,"Ч")
...

Sheet Итоги
A1: Итоги обзвона
A2: Считается автоматически по листу «Обзвон». Ничего заполнять не нужно.
A4: Окно | B4: Сделано звонков | C4: Ответил человек | D4: Гудки без ответа | E4: Доля гудков
A5: Рабочее время | B5: =COUNTA(Обзвон!$H$2:$H$42) | C5: =COUNTIF(Обзвон!$H$2:$H$42,"Ч") | D5: =COUNTIF(Обзвон!$H$2:$H$42,"Г") | E5: =IFERROR(COUNTIF(Обзвон!$H$2:$H$42,"Г")/COUNTA(Обзвон!$H$2:$H$42),"")
A6: Будний вечер | B6: =COUNTA(Обзвон!$I$2:$J$42) | C6: =COUNTIF(Обзвон!$I$2:$J$42,"Ч") | D6: =COUNTIF(Обзвон!$I$2:$J$42,"Г") | E6: =IFERROR(COUNTIF(Обзвон!$I$2:$J$42,"Г")/COUNTA(Обзвон!$I$2:$J$42),"")
A7: Суббота | B7: =COUNTA(Обзвон!$K$2:$L$42) | C7: =COUNTIF(Обзвон!$K$2:$L$42,"Ч") | D7: =COUNTIF(Обзвон!$K$2:$L$42,"Г") | E7: =IFERROR(COUNTIF(Обзвон!$K$2:$L$42,"Г")/COUNTA(Обзвон!$K$2:$L$42),"")
A8: Воскресенье | B8: =COUNTA(Обзвон!$M$2:$N$42) | C8: =COUNTIF(Обзвон!$M$2:$N$42,"Ч") | D8: =COUNTIF(Обзвон!$M$2:$N$42,"Г") | E8: =IFERROR(COUNTIF(Обзвон!$M$2:$N$42,"Г")/COUNTA(Обзвон!$M$2:$N$42),"")
A11: Что это значит
A12: Порог по вечернему окну | B12: =IF(E6="","нет данных",IF(E6>0.4,"Продолжаем — гипотеза держится",IF(E6<0.25,"Дверь закрыта — менять нишу или окно","Пограничная зона — смотреть качество ответов")))
A14: • Больше 40% гудков вечером — продолжаем.
A15: • Меньше 25% — клиники закрывают вечер сами, эта дверь не наша.
A16: • Между 25% и 40% — смотрим заметки: автоответчик без записи и «перезвоните завтра» считаем потерянным звонком.
A19: Кандидаты на разговор
A20: Отсортируйте лист «Обзвон» по колонке «Гудков» по убыванию. Сверху окажутся клиники, которые не ответили ни разу — с них и начинаем.
A22: Клиник, не ответивших ни разу (6 из 6) | B22: =COUNTIF(Обзвон!$O$2:$O$42,6)
A23: Клиник, где хотя бы раз ответил человек | B23: =COUNTIF(Обзвон!$P$2:$P$42,">0")
